<?xml version="1.0"?>
<robot xmlns:xacro="http://www.ros.org/wiki/xacro">

  <!-- Fanuc LR Mate 200iC/5H - generated from RoboDK .robot -->
  <xacro:macro name="lr_mate_200ic_5h" params="prefix parent *origin">

    <material name="${prefix}lr_mate_200ic_5h_grey"><color rgba="0.85 0.85 0.85 1.0"/></material>

    <joint name="${prefix}base_joint" type="fixed">
      <xacro:insert_block name="origin"/>
      <parent link="${parent}"/>
      <child link="${prefix}base_link"/>
    </joint>

    <link name="${prefix}base_link">
      <visual>
        <origin xyz="0 0 0" rpy="0 0 0"/>
        <geometry>
          <mesh filename="package://fanuc_robot_descriptions/meshes/lr_mate_200ic_5h/visual/base_link.dae" scale="0.001 0.001 0.001"/>
        </geometry>
      </visual>
      <collision>
        <origin xyz="0 0 0" rpy="0 0 0"/>
        <geometry>
          <mesh filename="package://fanuc_robot_descriptions/meshes/lr_mate_200ic_5h/collision/base_link.stl" scale="0.001 0.001 0.001"/>
        </geometry>
      </collision>
    </link>

    <link name="${prefix}link_1">
      <visual>
        <origin xyz="0 0 0" rpy="0 0 0"/>
        <geometry>
          <mesh filename="package://fanuc_robot_descriptions/meshes/lr_mate_200ic_5h/visual/link_1.dae" scale="0.001 0.001 0.001"/>
        </geometry>
      </visual>
      <collision>
        <origin xyz="0 0 0" rpy="0 0 0"/>
        <geometry>
          <mesh filename="package://fanuc_robot_descriptions/meshes/lr_mate_200ic_5h/collision/link_1.stl" scale="0.001 0.001 0.001"/>
        </geometry>
      </collision>
    </link>

    <link name="${prefix}link_2">
      <visual>
        <origin xyz="0 0 0" rpy="0 0 0"/>
        <geometry>
          <mesh filename="package://fanuc_robot_descriptions/meshes/lr_mate_200ic_5h/visual/link_2.dae" scale="0.001 0.001 0.001"/>
        </geometry>
      </visual>
      <collision>
        <origin xyz="0 0 0" rpy="0 0 0"/>
        <geometry>
          <mesh filename="package://fanuc_robot_descriptions/meshes/lr_mate_200ic_5h/collision/link_2.stl" scale="0.001 0.001 0.001"/>
        </geometry>
      </collision>
    </link>

    <link name="${prefix}link_3">
      <visual>
        <origin xyz="0 0 0" rpy="0 0 0"/>
        <geometry>
          <mesh filename="package://fanuc_robot_descriptions/meshes/lr_mate_200ic_5h/visual/link_3.dae" scale="0.001 0.001 0.001"/>
        </geometry>
      </visual>
      <collision>
        <origin xyz="0 0 0" rpy="0 0 0"/>
        <geometry>
          <mesh filename="package://fanuc_robot_descriptions/meshes/lr_mate_200ic_5h/collision/link_3.stl" scale="0.001 0.001 0.001"/>
        </geometry>
      </collision>
    </link>

    <link name="${prefix}link_4">
      <visual>
        <origin xyz="0 0 0" rpy="0 0 0"/>
        <geometry>
          <mesh filename="package://fanuc_robot_descriptions/meshes/lr_mate_200ic_5h/visual/link_4.dae" scale="0.001 0.001 0.001"/>
        </geometry>
      </visual>
      <collision>
        <origin xyz="0 0 0" rpy="0 0 0"/>
        <geometry>
          <mesh filename="package://fanuc_robot_descriptions/meshes/lr_mate_200ic_5h/collision/link_4.stl" scale="0.001 0.001 0.001"/>
        </geometry>
      </collision>
    </link>

    <link name="${prefix}link_5">
      <visual>
        <origin xyz="0 0 0" rpy="0 0 0"/>
        <geometry>
          <mesh filename="package://fanuc_robot_descriptions/meshes/lr_mate_200ic_5h/visual/link_5.dae" scale="0.001 0.001 0.001"/>
        </geometry>
      </visual>
      <collision>
        <origin xyz="0 0 0" rpy="0 0 0"/>
        <geometry>
          <mesh filename="package://fanuc_robot_descriptions/meshes/lr_mate_200ic_5h/collision/link_5.stl" scale="0.001 0.001 0.001"/>
        </geometry>
      </collision>
    </link>

    <joint name="${prefix}joint_1" type="revolute">
      <parent link="${prefix}base_link"/>
      <child link="${prefix}link_1"/>
      <origin xyz="0 0 0.33" rpy="0 -0 0"/>
      <axis xyz="0 0 1"/>
      <limit lower="-2.9670597" upper="2.9670597" effort="100.0" velocity="3.1416"/>
    </joint>

    <joint name="${prefix}joint_2" type="revolute">
      <parent link="${prefix}link_1"/>
      <child link="${prefix}link_2"/>
      <origin xyz="0.075 0 0" rpy="-1.5707963 -1.5707963 0"/>
      <axis xyz="0 0 1"/>
      <limit lower="-1.0471976" upper="2.443461" effort="100.0" velocity="3.1416"/>
    </joint>

    <joint name="${prefix}joint_3" type="revolute">
      <parent link="${prefix}link_2"/>
      <child link="${prefix}link_3"/>
      <origin xyz="0.3 0 0" rpy="0 -0 0"/>
      <axis xyz="0 0 1"/>
      <limit lower="-1.2217305" upper="2.9670597" effort="100.0" velocity="3.1416"/>
    </joint>

    <joint name="${prefix}joint_4" type="revolute">
      <parent link="${prefix}link_3"/>
      <child link="${prefix}link_4"/>
      <origin xyz="0.075 0.32 1.9594349e-17" rpy="-1.5707963 -0 0"/>
      <axis xyz="0 0 1"/>
      <limit lower="-3.3161256" upper="3.3161256" effort="100.0" velocity="3.1416"/>
    </joint>

    <joint name="${prefix}joint_5" type="revolute">
      <parent link="${prefix}link_4"/>
      <child link="${prefix}link_5"/>
      <origin xyz="0 0 0" rpy="1.5707963 -0 0"/>
      <axis xyz="0 0 1"/>
      <limit lower="-2.0071286" upper="2.0071286" effort="100.0" velocity="3.1416"/>
    </joint>

    <link name="${prefix}flange"/>
    <joint name="${prefix}link_5-flange" type="fixed">
      <parent link="${prefix}link_5"/>
      <child link="${prefix}flange"/>
      <origin xyz="0 0 0" rpy="0 0 0"/>
    </joint>
    <link name="${prefix}tool0"/>
    <joint name="${prefix}flange-tool0" type="fixed">
      <parent link="${prefix}flange"/>
      <child link="${prefix}tool0"/>
      <origin xyz="0 0 0" rpy="0 0 0"/>
    </joint>

  </xacro:macro>
</robot>
