<?xml version="1.0"?>
<robot xmlns:xacro="http://www.ros.org/wiki/xacro">

  <!-- Fanuc M-710iB/45 - generated from RoboDK .robot -->
  <xacro:macro name="m_710ib_45" params="prefix parent *origin">

    <material name="${prefix}m_710ib_45_grey"><color rgba="0.85 0.85 0.85 1.0"/></material>

    <joint name="${prefix}base_joint" type="fixed">
      <xacro:insert_block name="origin"/>
      <parent link="${parent}"/>
      <child link="${prefix}base_link"/>
    </joint>

    <link name="${prefix}base_link">
      <visual>
        <origin xyz="0 0 0" rpy="0 0 0"/>
        <geometry>
          <mesh filename="package://fanuc_robot_description/meshes/m_710ib_45/visual/base_link.dae" scale="0.001 0.001 0.001"/>
        </geometry>
      </visual>
      <collision>
        <origin xyz="0 0 0" rpy="0 0 0"/>
        <geometry>
          <mesh filename="package://fanuc_robot_description/meshes/m_710ib_45/collision/base_link.stl" scale="0.001 0.001 0.001"/>
        </geometry>
      </collision>
    </link>

    <link name="${prefix}link_1">
      <visual>
        <origin xyz="0 0 0" rpy="0 0 0"/>
        <geometry>
          <mesh filename="package://fanuc_robot_description/meshes/m_710ib_45/visual/link_1.dae" scale="0.001 0.001 0.001"/>
        </geometry>
      </visual>
      <collision>
        <origin xyz="0 0 0" rpy="0 0 0"/>
        <geometry>
          <mesh filename="package://fanuc_robot_description/meshes/m_710ib_45/collision/link_1.stl" scale="0.001 0.001 0.001"/>
        </geometry>
      </collision>
    </link>

    <link name="${prefix}link_2">
      <visual>
        <origin xyz="0 0 0" rpy="0 0 0"/>
        <geometry>
          <mesh filename="package://fanuc_robot_description/meshes/m_710ib_45/visual/link_2.dae" scale="0.001 0.001 0.001"/>
        </geometry>
      </visual>
      <collision>
        <origin xyz="0 0 0" rpy="0 0 0"/>
        <geometry>
          <mesh filename="package://fanuc_robot_description/meshes/m_710ib_45/collision/link_2.stl" scale="0.001 0.001 0.001"/>
        </geometry>
      </collision>
    </link>

    <link name="${prefix}link_3">
      <visual>
        <origin xyz="0 0 0" rpy="0 0 0"/>
        <geometry>
          <mesh filename="package://fanuc_robot_description/meshes/m_710ib_45/visual/link_3.dae" scale="0.001 0.001 0.001"/>
        </geometry>
      </visual>
      <collision>
        <origin xyz="0 0 0" rpy="0 0 0"/>
        <geometry>
          <mesh filename="package://fanuc_robot_description/meshes/m_710ib_45/collision/link_3.stl" scale="0.001 0.001 0.001"/>
        </geometry>
      </collision>
    </link>

    <link name="${prefix}link_4">
      <visual>
        <origin xyz="0 0 0" rpy="0 0 0"/>
        <geometry>
          <mesh filename="package://fanuc_robot_description/meshes/m_710ib_45/visual/link_4.dae" scale="0.001 0.001 0.001"/>
        </geometry>
      </visual>
      <collision>
        <origin xyz="0 0 0" rpy="0 0 0"/>
        <geometry>
          <mesh filename="package://fanuc_robot_description/meshes/m_710ib_45/collision/link_4.stl" scale="0.001 0.001 0.001"/>
        </geometry>
      </collision>
    </link>

    <link name="${prefix}link_5">
      <visual>
        <origin xyz="0 0 0" rpy="0 0 0"/>
        <geometry>
          <mesh filename="package://fanuc_robot_description/meshes/m_710ib_45/visual/link_5.dae" scale="0.001 0.001 0.001"/>
        </geometry>
      </visual>
      <collision>
        <origin xyz="0 0 0" rpy="0 0 0"/>
        <geometry>
          <mesh filename="package://fanuc_robot_description/meshes/m_710ib_45/collision/link_5.stl" scale="0.001 0.001 0.001"/>
        </geometry>
      </collision>
    </link>

    <link name="${prefix}link_6">
      <visual>
        <origin xyz="0 0 0" rpy="0 0 0"/>
        <geometry>
          <mesh filename="package://fanuc_robot_description/meshes/m_710ib_45/visual/link_6.dae" scale="0.001 0.001 0.001"/>
        </geometry>
      </visual>
      <collision>
        <origin xyz="0 0 0" rpy="0 0 0"/>
        <geometry>
          <mesh filename="package://fanuc_robot_description/meshes/m_710ib_45/collision/link_6.stl" scale="0.001 0.001 0.001"/>
        </geometry>
      </collision>
    </link>

    <joint name="${prefix}joint_1" type="revolute">
      <parent link="${prefix}base_link"/>
      <child link="${prefix}link_1"/>
      <origin xyz="0 0 0.65" rpy="0 -0 0"/>
      <axis xyz="0 0 1"/>
      <limit lower="-6.1086524" upper="5.5850536" effort="100.0" velocity="3.1416"/>
    </joint>

    <joint name="${prefix}joint_2" type="revolute">
      <parent link="${prefix}link_1"/>
      <child link="${prefix}link_2"/>
      <origin xyz="0 0 0" rpy="-1.5707963 -1.5707963 0"/>
      <axis xyz="0 0 1"/>
      <limit lower="-4.5378561" upper="4.5378561" effort="100.0" velocity="3.1416"/>
    </joint>

    <joint name="${prefix}joint_3" type="revolute">
      <parent link="${prefix}link_2"/>
      <child link="${prefix}link_3"/>
      <origin xyz="0.8 0 0" rpy="0 -0 0"/>
      <axis xyz="0 0 1"/>
      <limit lower="-7.3303829" upper="7.3303829" effort="100.0" velocity="3.1416"/>
    </joint>

    <joint name="${prefix}joint_4" type="revolute">
      <parent link="${prefix}link_3"/>
      <child link="${prefix}link_4"/>
      <origin xyz="0.1 0.9 5.5109106e-17" rpy="-1.5707963 -0 0"/>
      <axis xyz="0 0 1"/>
      <limit lower="-9.424778" upper="9.424778" effort="100.0" velocity="3.1416"/>
    </joint>

    <joint name="${prefix}joint_5" type="revolute">
      <parent link="${prefix}link_4"/>
      <child link="${prefix}link_5"/>
      <origin xyz="0 0 0" rpy="1.5707963 -0 0"/>
      <axis xyz="0 0 1"/>
      <limit lower="-4.3633231" upper="4.3633231" effort="100.0" velocity="3.1416"/>
    </joint>

    <joint name="${prefix}joint_6" type="revolute">
      <parent link="${prefix}link_5"/>
      <child link="${prefix}link_6"/>
      <origin xyz="1.1368684e-16 0.175 1.0715659e-17" rpy="-1.5707963 -0 0"/>
      <axis xyz="0 0 1"/>
      <limit lower="-12.566371" upper="12.566371" effort="100.0" velocity="3.1416"/>
    </joint>

    <link name="${prefix}flange"/>
    <joint name="${prefix}link_6-flange" type="fixed">
      <parent link="${prefix}link_6"/>
      <child link="${prefix}flange"/>
      <origin xyz="0 0 0" rpy="0 0 0"/>
    </joint>
    <link name="${prefix}tool0"/>
    <joint name="${prefix}flange-tool0" type="fixed">
      <parent link="${prefix}flange"/>
      <child link="${prefix}tool0"/>
      <origin xyz="0 0 0" rpy="0 0 0"/>
    </joint>

  </xacro:macro>
</robot>
